Workbook

Sheet Print_All
A1: บัญชีรายการชุดข้อมูลพื้นฐาน (Baseline Data Inventory)
A3: รหัส Dataset ID | B3: ชื่อชุดข้อมูล (TH) Dataset Name (Thai) | C3: ขอบข่าย / ข้อมูลย่อย / ประเภทข้อมูล Domain / Sub-Domain / Data Entity | D3: ภัยที่เกี่ยวข้อง Related Hazards | E3: ช่วงเวลา Time Period | F3: ความละเอียดเชิงเวลา Temporal Resolution | G3: ขอบเขต / ความละเอียดเชิงพื้นที่ Spatial Scope / Resolution | H3: รูปแบบไฟล์ / ระดับการเข้าถึง Format / Access Level | I3: URL
A4: BMA — กรุงเทพมหานคร
A5: =IFERROR(IF(BMA!A2="","",BMA!A2),"") -> BMA_1_1 | B5: =IFERROR(IF(BMA!B2="","",BMA!B2),"") -> ข้อมูลปริมาณน้ำฝนจากสถานีตรวจวัดของ กทม. (Rainfall measurements from BMA stations) | C5: =IFERROR(IF(BMA!A2="","",BMA!C2&CHAR(10)&BMA!D2&CHAR(10)&BMA!E2),"") -> IMPACT (Backward-looking) Hazard METEOROLOGICAL_OBSERVATION | D5: =IFERROR(IF(BMA!F2="","",BMA!F2),"") -> Flood (อุทกภัย); Storm (พายุ) | E5: =IFERROR(IF(BMA!I2="","",BMA!I2),"") -> - | F5: =IFERROR(IF(BMA!K2="","",BMA!K2),"") -> Real-time | G5: =IFERROR(IF(BMA!A2="","",BMA!L2&" / "&BMA!M2),"") -> Point / สถานีตรวจวัดของ กทม. | H5: =IFERROR(IF(BMA!A2="","",BMA!N2&" / "&BMA!O2),"") -> API / Web Service; CSV / Open | I5: =IFERROR(IF(BMA!P2="","",HYPERLINK(BMA!P2,IF(LEN(BMA!P2)>45,LEFT(BMA!P2,42)&"...",BMA!P2))),"") -> https://weather.bangkok.go.th
A6: =IFERROR(IF(BMA!A3="","",BMA!A3),"") -> BMA_1_2 | B6: =IFERROR(IF(BMA!B3="","",BMA!B3),"") -> ข้อมูลภาพเรดาร์ตรวจฝน (Rainfall radar data) | C6: =IFERROR(IF(BMA!A3="","",BMA!C3&CHAR(10)&BMA!D3&CHAR(10)&BMA!E3),"") -> Forward-looking Hazard METEOROLOGICAL_OBSERVATION | D6: =IFERROR(IF(BMA!F3="","",BMA!F3),"") -> Flood (อุทกภัย); Storm (พายุ) | E6: =IFERROR(IF(BMA!I3="","",BMA!I3),"") -> - | F6: =IFERROR(IF(BMA!K3="","",BMA!K3),"") -> Sub-daily | G6: =IFERROR(IF(BMA!A3="","",BMA!L3&" / "&BMA!M3),"") -> Sub-national / - | H6: =IFERROR(IF(BMA!A3="","",BMA!N3&" / "&BMA!O3),"") -> Image; API / Web Service / Open | I6: =IFERROR(IF(BMA!P3="","",HYPERLINK(BMA!P3,IF(LEN(BMA!P3)>45,LEFT(BMA!P3,42)&"...",BMA!P3))),"") -> https://weather.bangkok.go.th
A7: =IFERROR(IF(BMA!A4="","",BMA!A4),"") -> BMA_2_1 | B7: =IFERROR(IF(BMA!B4="","",BMA!B4),"") -> ข้อมูลระดับน้ำในคลอง (Canal water levels) | C7: =IFERROR(IF(BMA!A4="","",BMA!C4&CHAR(10)&BMA!D4&CHAR(10)&BMA!E4),"") -> IMPACT (Backward-looking) Hazard HAZARDOUS_EVENT | D7: =IFERROR(IF(BMA!F4="","",BMA!F4),"") -> Flood (อุทกภัย) | E7: =IFERROR(IF(BMA!I4="","",BMA!I4),"") -> - | F7: =IFERROR(IF(BMA!K4="","",BMA!K4),"") -> Real-time | G7: =IFERROR(IF(BMA!A4="","",BMA!L4&" / "&BMA!M4),"") -> Point / คลอง/ประตูระบายน้ำ | H7: =IFERROR(IF(BMA!A4="","",BMA!N4&" / "&BMA!O4),"") -> API / Web Service / Open | I7: =IFERROR(IF(BMA!P4="","",HYPERLINK(BMA!P4,IF(LEN(BMA!P4)>45,LEFT(BMA!P4,42)&"...",BMA!P4))),"") -> https://data.bangkok.go.th/th/
A8: =IFERROR(IF(BMA!A5="","",BMA!A5),"") -> BMA_2_2 | B8: =IFERROR(IF(BMA!B5="","",BMA!B5),"") -> ข้อมูลตรวจวัดน้ำท่วมถนน (Road-flood monitoring data) | C8: =IFERROR(IF(BMA!A5="","",BMA!C5&CHAR(10)&BMA!D5&CHAR(10)&BMA!E5),"") -> IMPACT (Backward-looking) Disaster Record DISASTER_RECORD | D8: =IFERROR(IF(BMA!F5="","",BMA!F5),"") -> Flood (อุทกภัย) | E8: =IFERROR(IF(BMA!I5="","",BMA!I5),"") -> - | F8: =IFERROR(IF(BMA!K5="","",BMA!K5),"") -> Real-time | G8: =IFERROR(IF(BMA!A5="","",BMA!L5&" / "&BMA!M5),"") -> Point / จุดตรวจวัด | H8: =IFERROR(IF(BMA!A5="","",BMA!N5&" / "&BMA!O5),"") -> API / Web Service / Open | I8: =IFERROR(IF(BMA!P5="","",HYPERLINK(BMA!P5,IF(LEN(BMA!P5)>45,LEFT(BMA!P5,42)&"...",BMA!P5))),"") -> https://data.bangkok.go.th/th/
A9: =IFERROR(IF(BMA!A6="","",BMA!A6),"") -> BMA_2_3 | B9: =IFERROR(IF(BMA!B6="","",BMA!B6),"") -> ฐานข้อมูลทรัพย์สินระบบระบายน้ำ ท่อ คลอง อุโมงค์ สถานีสูบน้ำ ประตูระบายน้ำ (Drainage system asset inventory) | C9: =IFERROR(IF(BMA!A6="","",BMA!C6&CHAR(10)&BMA!D6&CHAR(10)&BMA!E6),"") -> Spatial Unit Exposure EXPOSED_ASSET | D9: =IFERROR(IF(BMA!F6="","",BMA!F6),"") -> Flood (อุทกภัย) | E9: =IFERROR(IF(BMA!I6="","",BMA!I6),"") -> - | F9: =IFERROR(IF(BMA!K6="","",BMA!K6),"") -> Annual | G9: =IFERROR(IF(BMA!A6="","",BMA!L6&" / "&BMA!M6),"") -> Sub-national / ทั่วพื้นที่ กทม. | H9: =IFERROR(IF(BMA!A6="","",BMA!N6&" / "&BMA!O6),"") -> Shapefile; Database / Restricted | I9: =IFERROR(IF(BMA!P6="","",HYPERLINK(BMA!P6,IF(LEN(BMA!P6)>45,LEFT(BMA!P6,42)&"...",BMA!P6))),"") -> https://data.bangkok.go.th/th/
A10: =IFERROR(IF(BMA!A7="","",BMA!A7),"") -> BMA_2_4 | B10: =IFERROR(IF(BMA!B7="","",BMA!B7),"") -> ข้อมูลห้องและจุดคลายร้อนของ กทม. (Cooling rooms / cooling points) | C10: =IFERROR(IF(BMA!A7="","",BMA!C7&CHAR(10)&BMA!D7&CHAR(10)&BMA!E7),"") -> Adaptation Planning Response RESPONSE | D10: =IFERROR(IF(BMA!F7="","",BMA!F7),"") -> Heat (คลื่นความร้อน) | E10: =IFERROR(IF(BMA!I7="","",BMA!I7),"") -> 2569 (2026) | F10: =IFERROR(IF(BMA!K7="","",BMA!K7),"") -> Annual | G10: =IFERROR(IF(BMA!A7="","",BMA!L7&" / "&BMA!M7),"") -> Sub-national / ทั่วพื้นที่ กทม. | H10: =IFERROR(IF(BMA!A7="","",BMA!N7&" / "&BMA!O7),"") -> Database; PDF Report / Open | I10: =IFERROR(IF(BMA!P7="","",HYPERLINK(BMA!P7,IF(LEN(BMA!P7)>45,LEFT(BMA!P7,42)&"...",BMA!P7))),"") -> https://data.bangkok.go.th/th/
A11: =IFERROR(IF(BMA!A8="","",BMA!A8),"") -> BMA_3_1 | B11: =IFERROR(IF(BMA!B8="","",BMA!B8),"") -> ข้อมูลคุณภาพอากาศและดัชนีความร้อนของ กทม. (Air quality monitoring & Heat Index) | C11: =IFERROR(IF(BMA!A8="","",BMA!C8&CHAR(10)&BMA!D8&CHAR(10)&BMA!E8),"") -> IMPACT (Backward-looking) Hazard ENVIRONMENT | D11: =IFERROR(IF(BMA!F8="","",BMA!F8),"") -> Heat (คลื่นความร้อน); Air Quality / Haze (คุณภาพอากาศ / หมอกควัน) | E11: =IFERROR(IF(BMA!I8="","",BMA!I8),"") -> - | F11: =IFERROR(IF(BMA!K8="","",BMA!K8),"") -> Real-time | G11: =IFERROR(IF(BMA!A8="","",BMA!L8&" / "&BMA!M8),"") -> Point / สถานีตรวจวัด | H11: =IFERROR(IF(BMA!A8="","",BMA!N8&" / "&BMA!O8),"") -> API / Web Service / Open | I11: =IFERROR(IF(BMA!P8="","",HYPERLINK(BMA!P8,IF(LEN(BMA!P8)>45,LEFT(BMA!P8,42)&"...",BMA!P8))),"") -> https://airbkk.com
A12: CDD — กรมการพัฒนาชุมชน
A13: =IFERROR(IF(CDD!A2="","",CDD!A2),"") -> CDD_1_1 | B13: =IFERROR(IF(CDD!B2="","",CDD!B2),"") -> จำนวนครัวเรือนกลุ่มเปราะบาง | C13: =IFERROR(IF(CDD!A2="","",CDD!C2&CHAR(10)&CDD!D2&CHAR(10)&CDD!E2),"") -> Forward-looking Vulnerability SENSITIVITY | D13: =IFERROR(IF(CDD!F2="","",CDD!F2),"") -> Cross-cutting (ทุกภัย) | E13: =IFERROR(IF(CDD!I2="","",CDD!I2),"") -> 2025 หรือล่าสุด | F13: =IFERROR(IF(CDD!K2="","",CDD!K2),"") -> Annual | G13: =IFERROR(IF(CDD!A2="","",CDD!L2&" / "&CDD!M2),"") -> National / Mooban | H13: =IFERROR(IF(CDD!A2="","",CDD!N2&" / "&CDD!O2),"") -> Shapefile / Vector; CSV; API / Web Service / Restricted | I13: =IFERROR(IF(CDD!P2="","",HYPERLINK(CDD!P2,IF(LEN(CDD!P2)>45,LEFT(CDD!P2,42)&"...",CDD!P2))),"") -> https://dashboard66.cdd.go.th/Home/DashBoa...
A14: DCCE — กรมการเปลี่ยนแปลงสภาพภูมิอากาศและสิ่งแวดล้อม
A15: =IFERROR(IF(DCCE!A2="","",DCCE!A2),"") -> DCCE_2_1 | B15: =IFERROR(IF(DCCE!B2="","",DCCE!B2),"") -> ปริมาณน้ำฝน (GridData, historical) | C15: =IFERROR(IF(DCCE!A2="","",DCCE!C2&CHAR(10)&DCCE!D2&CHAR(10)&DCCE!E2),"") -> Forward-looking Climate Driver CLIMATE_DRIVER | D15: =IFERROR(IF(DCCE!F2="","",DCCE!F2),"") -> Drought (ภัยแล้ง) | E15: =IFERROR(IF(DCCE!I2="","",DCCE!I2),"") -> 1981-2023 | F15: =IFERROR(IF(DCCE!K2="","",DCCE!K2),"") -> Daily; Monthly | G15: =IFERROR(IF(DCCE!A2="","",DCCE!L2&" / "&DCCE!M2),"") -> National / 25 km (Grid) | H15: =IFERROR(IF(DCCE!A2="","",DCCE!N2&" / "&DCCE!O2),"") -> NetCDF / Restricted | I15: =IFERROR(IF(DCCE!P2="","",HYPERLINK(DCCE!P2,IF(LEN(DCCE!P2)>45,LEFT(DCCE!P2,42)&"...",DCCE!P2))),"") -> https://clim-webbased.dcce.go.th/DataServices
A16: =IFERROR(IF(DCCE!A3="","",DCCE!A3),"") -> DCCE_2_10 | B16: =IFERROR(IF(DCCE!B3="","",DCCE!B3),"") -> ความชื้นสัมพัทธ์ (WRF-Chem) | C16: =IFERROR(IF(DCCE!A3="","",DCCE!C3&CHAR(10)&DCCE!D3&CHAR(10)&DCCE!E3),"") -> Forward-looking Climate Driver CLIMATE_DRIVER | D16: =IFERROR(IF(DCCE!F3="","",DCCE!F3),"") -> ภัยแล้ง (Drought); ไฟป่า (Wildfire) | E16: =IFERROR(IF(DCCE!I3="","",DCCE!I3),"") -> 1981-2014 (historical); 2015-2099 (ssp585) | F16: =IFERROR(IF(DCCE!K3="","",DCCE!K3),"") -> Daily; Monthly | G16: =IFERROR(IF(DCCE!A3="","",DCCE!L3&" / "&DCCE!M3),"") -> National / 25 km (Grid) | H16: =IFERROR(IF(DCCE!A3="","",DCCE!N3&" / "&DCCE!O3),"") -> NetCDF / Restricted | I16: =IFERROR(IF(DCCE!P3="","",HYPERLINK(DCCE!P3,IF(LEN(DCCE!P3)>45,LEFT(DCCE!P3,42)&"...",DCCE!P3))),"") -> https://clim-webbased.dcce.go.th/DataServices
A17: =IFERROR(IF(DCCE!A4="","",DCCE!A4),"") -> DCCE_2_11 | B17: =IFERROR(IF(DCCE!B4="","",DCCE!B4),"") -> ปริมาณน้ำฝน (RegCM5, EC-Earth3-Veg) | C17: =IFERROR(IF(DCCE!A4="","",DCCE!C4&CHAR(10)&DCCE!D4&CHAR(10)&DCCE!E4),"") -> Forward-looking Climate Driver CLIMATE_DRIVER | D17: =IFERROR(IF(DCCE!F4="","",DCCE!F4),"") -> น้ำท่วม (Flood); ภัยแล้ง (Drought) | E17: =IFERROR(IF(DCCE!I4="","",DCCE!I4),"") -> 1960-2014 (historical); 2015-2099 (ssp245); 2015-2099 (ssp585) | F17: =IFERROR(IF(DCCE!K4="","",DCCE!K4),"") -> Daily; Monthly | G17: =IFERROR(IF(DCCE!A4="","",DCCE!L4&" / "&DCCE!M4),"") -> National / 25 km (Grid) | H17: =IFERROR(IF(DCCE!A4="","",DCCE!N4&" / "&DCCE!O4),"") -> NetCDF / Restricted | I17: =IFERROR(IF(DCCE!P4="","",HYPERLINK(DCCE!P4,IF(LEN(DCCE!P4)>45,LEFT(DCCE!P4,42)&"...",DCCE!P4))),"") -> https://clim-webbased.dcce.go.th/DataServices
A18: =IFERROR(IF(DCCE!A5="","",DCCE!A5),"") -> DCCE_2_12 | B18: =IFERROR(IF(DCCE!B5="","",DCCE!B5),"") -> อุณหภูมิสูงสุด (RegCM5, EC-Earth3-Veg) | C18: =IFERROR(IF(DCCE!A5="","",DCCE!C5&CHAR(10)&DCCE!D5&CHAR(10)&DCCE!E5),"") -> Forward-looking Climate Driver CLIMATE_DRIVER | D18: =IFERROR(IF(DCCE!F5="","",DCCE!F5),"") -> คลื่นความร้อน (Heat); ภัยแล้ง (Drought) | E18: =IFERROR(IF(DCCE!I5="","",DCCE!I5),"") -> 1960-2014 (historical); 2015-2099 (ssp245); 2015-2099 (ssp585) | F18: =IFERROR(IF(DCCE!K5="","",DCCE!K5),"") -> Daily; Monthly | G18: =IFERROR(IF(DCCE!A5="","",DCCE!L5&" / "&DCCE!M5),"") -> National / 25 km (Grid) | H18: =IFERROR(IF(DCCE!A5="","",DCCE!N5&" / "&DCCE!O5),"") -> NetCDF / Restricted | I18: =IFERROR(IF(DCCE!P5="","",HYPERLINK(DCCE!P5,IF(LEN(DCCE!P5)>45,LEFT(DCCE!P5,42)&"...",DCCE!P5))),"") -> https://clim-webbased.dcce.go.th/DataServices
A19: =IFERROR(IF(DCCE!A6="","",DCCE!A6),"") -> DCCE_2_13 | B19: =IFERROR(IF(DCCE!B6="","",DCCE!B6),"") -> อุณหภูมิต่ำสุด (RegCM5, EC-Earth3-Veg) | C19: =IFERROR(IF(DCCE!A6="","",DCCE!C6&CHAR(10)&DCCE!D6&CHAR(10)&DCCE!E6),"") -> Forward-looking Climate Driver CLIMATE_DRIVER | D19: =IFERROR(IF(DCCE!F6="","",DCCE!F6),"") -> คลื่นความเย็น (Cold spell); คลื่นความร้อน (Heat) | E19: =IFERROR(IF(DCCE!I6="","",DCCE!I6),"") -> 1960-2014 (historical); 2015-2099 (ssp245); 2015-2099 (ssp585) | F19: =IFERROR(IF(DCCE!K6="","",DCCE!K6),"") -> Daily; Monthly | G19: =IFERROR(IF(DCCE!A6="","",DCCE!L6&" / "&DCCE!M6),"") -> National / 25 km (Grid) | H19: =IFERROR(IF(DCCE!A6="","",DCCE!N6&" / "&DCCE!O6),"") -> NetCDF / Restricted | I19: =IFERROR(IF(DCCE!P6="","",HYPERLINK(DCCE!P6,IF(LEN(DCCE!P6)>45,LEFT(DCCE!P6,42)&"...",DCCE!P6))),"") -> https://clim-webbased.dcce.go.th/DataServices
A20: =IFERROR(IF(DCCE!A7="","",DCCE!A7),"") -> DCCE_2_14 | B20: =IFERROR(IF(DCCE!B7="","",DCCE!B7),"") -> อุณหภูมิเฉลี่ย (RegCM5, EC-Earth3-Veg) | C20: =IFERROR(IF(DCCE!A7="","",DCCE!C7&CHAR(10)&DCCE!D7&CHAR(10)&DCCE!E7),"") -> Forward-looking Climate Driver CLIMATE_DRIVER | D20: =IFERROR(IF(DCCE!F7="","",DCCE!F7),"") -> Multi-hazard | E20: =IFERROR(IF(DCCE!I7="","",DCCE!I7),"") -> 1960-2014 (historical); 2015-2099 (ssp245); 2015-2099 (ssp585) | F20: =IFERROR(IF(DCCE!K7="","",DCCE!K7),"") -> Daily; Monthly | G20: =IFERROR(IF(DCCE!A7="","",DCCE!L7&" / "&DCCE!M7),"") -> National / 25 km (Grid) | H20: =IFERROR(IF(DCCE!A7="","",DCCE!N7&" / "&DCCE!O7),"") -> NetCDF / Restricted | I20: =IFERROR(IF(DCCE!P7="","",HYPERLINK(DCCE!P7,IF(LEN(DCCE!P7)>45,LEFT(DCCE!P7,42)&"...",DCCE!P7))),"") -> https://clim-webbased.dcce.go.th/DataServices
A21: =IFERROR(IF(DCCE!A8="","",DCCE!A8),"") -> DCCE_2_15 | B21: =IFERROR(IF(DCCE!B8="","",DCCE!B8),"") -> ความชื้นสัมพัทธ์ (RegCM5, EC-Earth3-Veg) | C21: =IFERROR(IF(DCCE!A8="","",DCCE!C8&CHAR(10)&DCCE!D8&CHAR(10)&DCCE!E8),"") -> Forward-looking Climate Driver CLIMATE_DRIVER | D21: =IFERROR(IF(DCCE!F8="","",DCCE!F8),"") -> ภัยแล้ง (Drought); ไฟป่า (Wildfire) | E21: =IFERROR(IF(DCCE!I8="","",DCCE!I8),"") -> 1960-2014 (historical); 2015-2099 (ssp245); 2015-2099 (ssp585) | F21: =IFERROR(IF(DCCE!K8="","",DCCE!K8),"") -> Daily; Monthly | G21: =IFERROR(IF(DCCE!A8="","",DCCE!L8&" / "&DCCE!M8),"") -> National / 25 km (Grid) | H21: =IFERROR(IF(DCCE!A8="","",DCCE!N8&" / "&DCCE!O8),"") -> NetCDF / Restricted | I21: =IFERROR(IF(DCCE!P8="","",HYPERLINK(DCCE!P8,IF(LEN(DCCE!P8)>45,LEFT(DCCE!P8,42)&"...",DCCE!P8))),"") -> https://clim-webbased.dcce.go.th/DataServices
A22: =IFERROR(IF(DCCE!A9="","",DCCE!A9),"") -> DCCE_2_16 | B22: =IFERROR(IF(DCCE!B9="","",DCCE!B9),"") -> ปริมาณน้ำฝน (Statistical Downscaling, CMIP6) | C22: =IFERROR(IF(DCCE!A9="","",DCCE!C9&CHAR(10)&DCCE!D9&CHAR(10)&DCCE!E9),"") -> Forward-looking Climate Driver CLIMATE_DRIVER | D22: =IFERROR(IF(DCCE!F9="","",DCCE!F9),"") -> น้ำท่วม (Flood); ภัยแล้ง (Drought) | E22: =IFERROR(IF(DCCE!I9="","",DCCE!I9),"") -> 1981-2014 (historical); 2015-2100 (ssp245); 2015-2100 (ssp585) | F22: =IFERROR(IF(DCCE!K9="","",DCCE!K9),"") -> Daily; Monthly | G22: =IFERROR(IF(DCCE!A9="","",DCCE!L9&" / "&DCCE!M9),"") -> National / 5 km (Grid) | H22: =IFERROR(IF(DCCE!A9="","",DCCE!N9&" / "&DCCE!O9),"") -> NetCDF / Restricted | I22: =IFERROR(IF(DCCE!P9="","",HYPERLINK(DCCE!P9,IF(LEN(DCCE!P9)>45,LEFT(DCCE!P9,42)&"...",DCCE!P9))),"") -> https://clim-webbased.dcce.go.th/DataServices
A23: =IFERROR(IF(DCCE!A10="","",DCCE!A10),"") -> DCCE_2_17 | B23: =IFERROR(IF(DCCE!B10="","",DCCE!B10),"") -> อุณหภูมิสูงสุด (Statistical Downscaling, CMIP6) | C23: =IFERROR(IF(DCCE!A10="","",DCCE!C10&CHAR(10)&DCCE!D10&CHAR(10)&DCCE!E10),"") -> Forward-looking Climate Driver CLIMATE_DRIVER | D23: =IFERROR(IF(DCCE!F10="","",DCCE!F10),"") -> คลื่นความร้อน (Heat); ภัยแล้ง (Drought) | E23: =IFERROR(IF(DCCE!I10="","",DCCE!I10),"") -> 1981-2014 (historical); 2015-2100 (ssp245); 2015-2100 (ssp585) | F23: =IFERROR(IF(DCCE!K10="","",DCCE!K10),"") -> Daily; Monthly | G23: =IFERROR(IF(DCCE!A10="","",DCCE!L10&" / "&DCCE!M10),"") -> National / 5 km (Grid) | H23: =IFERROR(IF(DCCE!A10="","",DCCE!N10&" / "&DCCE!O10),"") -> NetCDF / Restricted | I23: =IFERROR(IF(DCCE!P10="","",HYPERLINK(DCCE!P10,IF(LEN(DCCE!P10)>45,LEFT(DCCE!P10,42)&"...",DCCE!P10))),"") -> https://clim-webbased.dcce.go.th/DataServices
A24: =IFERROR(IF(DCCE!A11="","",DCCE!A11),"") -> DCCE_2_18 | B24: =IFERROR(IF(DCCE!B11="","",DCCE!B11),"") -> อุณหภูมิต่ำสุด (Statistical Downscaling, CMIP6) | C24: =IFERROR(IF(DCCE!A11="","",DCCE!C11&CHAR(10)&DCCE!D11&CHAR(10)&DCCE!E11),"") -> Forward-looking Climate Driver CLIMATE_DRIVER | D24: =IFERROR(IF(DCCE!F11="","",DCCE!F11),"") -> คลื่นความเย็น (Cold spell); คลื่นความร้อน (Heat) | E24: =IFERROR(IF(DCCE!I11="","",DCCE!I11),"") -> 1981-2014 (historical); 2015-2100 (ssp245); 2015-2100 (ssp585) | F24: =IFERROR(IF(DCCE!K11="","",DCCE!K11),"") -> Daily; Monthly | G24: =IFERROR(IF(DCCE!A11="","",DCCE!L11&" / "&DCCE!M11),"") -> National / 5 km (Grid) | H24: =IFERROR(IF(DCCE!A11="","",DCCE!N11&" / "&DCCE!O11),"") -> NetCDF / Restricted | I24: =IFERROR(IF(DCCE!P11="","",HYPERLINK(DCCE!P11,IF(LEN(DCCE!P11)>45,LEFT(DCCE!P11,42)&"...",DCCE!P11))),"") -> https://clim-webbased.dcce.go.th/DataServices
A25: =IFERROR(IF(DCCE!A12="","",DCCE!A12),"") -> DCCE_2_19 | B25: =IFERROR(IF(DCCE!B12="","",DCCE!B12),"") -> อุณหภูมิเฉลี่ย (Statistical Downscaling, CMIP6) | C25: =IFERROR(IF(DCCE!A12="","",DCCE!C12&CHAR(10)&DCCE!D12&CHAR(10)&DCCE!E12),"") -> Forward-looking Climate Driver CLIMATE_DRIVER | D25: =IFERROR(IF(DCCE!F12="","",DCCE!F12),"") -> Multi-hazard | E25: =IFERROR(IF(DCCE!I12="","",DCCE!I12),"") -> 1981-2014 (historical); 2015-2100 (ssp245); 2015-2100 (ssp585) | F25: =IFERROR(IF(DCCE!K12="","",DCCE!K12),"") -> Daily; Monthly | G25: =IFERROR(IF(DCCE!A12="","",DCCE!L12&" / "&DCCE!M12),"") -> National / 5 km (Grid) | H25: =IFERROR(IF(DCCE!A12="","",DCCE!N12&" / "&DCCE!O12),"") -> NetCDF / Restricted | I25: =IFERROR(IF(DCCE!P12="","",HYPERLINK(DCCE!P12,IF(LEN(DCCE!P12)>45,LEFT(DCCE!P12,42)&"...",DCCE!P12))),"") -> https://clim-webbased.dcce.go.th/DataServices
A26: =IFERROR(IF(DCCE!A13="","",DCCE!A13),"") -> DCCE_2_2 | B26: =IFERROR(IF(DCCE!B13="","",DCCE!B13),"") -> อุณหภูมิสูงสุด (GridData, historical) | C26: =IFERROR(IF(DCCE!A13="","",DCCE!C13&CHAR(10)&DCCE!D13&CHAR(10)&DCCE!E13),"") -> Forward-looking Climate Driver CLIMATE_DRIVER | D26: =IFERROR(IF(DCCE!F13="","",DCCE!F13),"") -> Drought (ภัยแล้ง) | E26: =IFERROR(IF(DCCE!I13="","",DCCE!I13),"") -> 1981-2023 | F26: =IFERROR(IF(DCCE!K13="","",DCCE!K13),"") -> Daily; Monthly | G26: =IFERROR(IF(DCCE!A13="","",DCCE!L13&" / "&DCCE!M13),"") -> National / 25 km (Grid) | H26: =IFERROR(IF(DCCE!A13="","",DCCE!N13&" / "&DCCE!O13),"") -> NetCDF / Restricted | I26: =IFERROR(IF(DCCE!P13="","",HYPERLINK(DCCE!P13,IF(LEN(DCCE!P13)>45,LEFT(DCCE!P13,42)&"...",DCCE!P13))),"") -> https://clim-webbased.dcce.go.th/DataServices
... A40: =IFERROR(IF(DCCE!A27="","",DCCE!A27),"") -> DCCE_3_7 | B40: =IFERROR(IF(DCCE!B27="","",DCCE!B27),"") -> ดัชนีภูมิอากาศ | C40: =IFERROR(IF(DCCE!A27="","",DCCE!C27&CHAR(10)&DCCE!D27&CHAR(10)&DCCE!E27),"") -> Forward-looking Climate Driver CLIMATE_DRIVER | D40: =IFERROR(IF(DCCE!F27="","",DCCE!F27),"") -> Cross-cutting (ทุกภัย) | E40: =IFERROR(IF(DCCE!I27="","",DCCE!I27),"") -> 1960-2014; 2015-2040; 2041-2060; 2061-2080; 2081-2106 | F40: =IFERROR(IF(DCCE!K27="","",DCCE!K27),"") -> Annual | G40: =IFERROR(IF(DCCE!A27="","",DCCE!L27&" / "&DCCE!M27),"") -> National / Province | H40: =IFERROR(IF(DCCE!A27="","",DCCE!N27&" / "&DCCE!O27),"") -> CSV / Open | I40: =IFERROR(IF(DCCE!P27="","",HYPERLINK(DCCE!P27,IF(LEN(DCCE!P27)>45,LEFT(DCCE!P27,42)&"...",DCCE!P27))),"") -> https://ccic.dcce.go.th/riskarea
A41: DDPM — กรมป้องกันและบรรเทาสาธารณภัย
A42: =IFERROR(IF(DDPM!A2="","",DDPM!A2),"") -> DDPM_1_1 | B42: =IFERROR(IF(DDPM!B2="","",DDPM!B2),"") -> แผนที่ความเสี่ยงอุทกภัย | C42: =IFERROR(IF(DDPM!A2="","",DDPM!C2&CHAR(10)&DDPM!D2&CHAR(10)&DDPM!E2),"") -> Forward-looking Hazard HAZARD_MAP | D42: =IFERROR(IF(DDPM!F2="","",DDPM!F2),"") -> Flood (อุทกภัย) | E42: =IFERROR(IF(DDPM!I2="","",DDPM!I2),"") -> 2016-2025 | F42: =IFERROR(IF(DDPM!K2="","",DDPM!K2),"") -> Annual | G42: =IFERROR(IF(DDPM!A2="","",DDPM!L2&" / "&DDPM!M2),"") -> National / - | H42: =IFERROR(IF(DDPM!A2="","",DDPM!N2&" / "&DDPM!O2),"") -> Shapefile / Vector; CSV; API / Web Service / Restricted | I42: =IFERROR(IF(DDPM!P2="","",HYPERLINK(DDPM!P2,IF(LEN(DDPM!P2)>45,LEFT(DDPM!P2,42)&"...",DDPM!P2))),"") -> -
A43: =IFERROR(IF(DDPM!A3="","",DDPM!A3),"") -> DDPM_2_1 | B43: =IFERROR(IF(DDPM!B3="","",DDPM!B3),"") -> ข้อมูลเหตุการณ์ภัยพิบัติย้อนหลัง 10 ปี (10-year historical disaster occurrence data) | C43: =IFERROR(IF(DDPM!A3="","",DDPM!C3&CHAR(10)&DDPM!D3&CHAR(10)&DDPM!E3),"") -> IMPACT (Backward-looking) Disaster Record DISASTER_RECORD | D43: =IFERROR(IF(DDPM!F3="","",DDPM!F3),"") -> Cross-cutting (ทุกภัย) | E43: =IFERROR(IF(DDPM!I3="","",DDPM!I3),"") -> Unknown | F43: =IFERROR(IF(DDPM!K3="","",DDPM!K3),"") -> Event-based | G43: =IFERROR(IF(DDPM!A3="","",DDPM!L3&" / "&DDPM!M3),"") -> Mooban / Mooban | H43: =IFERROR(IF(DDPM!A3="","",DDPM!N3&" / "&DDPM!O3),"") -> Database / Restricted | I43: =IFERROR(IF(DDPM!P3="","",HYPERLINK(DDPM!P3,IF(LEN(DDPM!P3)>45,LEFT(DDPM!P3,42)&"...",DDPM!P3))),"") -> -
A44: =IFERROR(IF(DDPM!A4="","",DDPM!A4),"") -> DDPM_2_2 | B44: =IFERROR(IF(DDPM!B4="","",DDPM!B4),"") -> ข้อมูลผลการประเมินความเสี่ยงด้านสภาพภูมิอากาศภาคเหนือ 17 จังหวัด (Northern Region Climate Risk Assessment) | C44: =IFERROR(IF(DDPM!A4="","",DDPM!C4&CHAR(10)&DDPM!D4&CHAR(10)&DDPM!E4),"") -> Forward-looking Risk Metric COMPOSITE_INDEX | D44: =IFERROR(IF(DDPM!F4="","",DDPM!F4),"") -> Flood (อุทกภัย); Landslide (ดินถล่ม) | E44: =IFERROR(IF(DDPM!I4="","",DDPM!I4),"") -> Unknown | F44: =IFERROR(IF(DDPM!K4="","",DDPM!K4),"") -> Annual | G44: =IFERROR(IF(DDPM!A4="","",DDPM!L4&" / "&DDPM!M4),"") -> Sub-national / Sub-district | H44: =IFERROR(IF(DDPM!A4="","",DDPM!N4&" / "&DDPM!O4),"") -> PDF Report; Shapefile / Restricted | I44: =IFERROR(IF(DDPM!P4="","",HYPERLINK(DDPM!P4,IF(LEN(DDPM!P4)>45,LEFT(DDPM!P4,42)&"...",DDPM!P4))),"") -> -
A45: =IFERROR(IF(DDPM!A5="","",DDPM!A5),"") -> DDPM_2_3 | B45: =IFERROR(IF(DDPM!B5="","",DDPM!B5),"") -> ข้อมูลความเสียหายของทรัพย์สิน (ถนน ปศุสัตว์ วัด ฯลฯ) ตามรายงานของ อปท. (LAO-reported damage counts) | C45: =IFERROR(IF(DDPM!A5="","",DDPM!C5&CHAR(10)&DDPM!D5&CHAR(10)&DDPM!E5),"") -> IMPACT (Backward-looking) Loss & Damage LOSS_DAMAGE_RECORD | D45: =IFERROR(IF(DDPM!F5="","",DDPM!F5),"") -> Flood (อุทกภัย); Storm (พายุ); Drought (ภัยแล้ง) | E45: =IFERROR(IF(DDPM!I5="","",DDPM!I5),"") -> Unknown | F45: =IFERROR(IF(DDPM!K5="","",DDPM!K5),"") -> Event-based | G45: =IFERROR(IF(DDPM!A5="","",DDPM!L5&" / "&DDPM!M5),"") -> Mooban / Mooban | H45: =IFERROR(IF(DDPM!A5="","",DDPM!N5&" / "&DDPM!O5),"") -> Database / Restricted | I45: =IFERROR(IF(DDPM!P5="","",HYPERLINK(DDPM!P5,IF(LEN(DDPM!P5)>45,LEFT(DDPM!P5,42)&"...",DDPM!P5))),"") -> -
A46: =IFERROR(IF(DDPM!A6="","",DDPM!A6),"") -> DDPM_3_1 | B46: =IFERROR(IF(DDPM!B6="","",DDPM!B6),"") -> พื้นที่ประสบภัยน้ำแล้งรุนแรง | C46: =IFERROR(IF(DDPM!A6="","",DDPM!C6&CHAR(10)&DDPM!D6&CHAR(10)&DDPM!E6),"") -> Forward-looking Hazard HAZARDOUS_EVENT | D46: =IFERROR(IF(DDPM!F6="","",DDPM!F6),"") -> Drought (ภัยแล้ง); Heat (คลื่นความร้อน) | E46: =IFERROR(IF(DDPM!I6="","",DDPM!I6),"") -> 1960-2014; 2015-2040; 2041-2060; 2061-2080; 2081-2100 | F46: =IFERROR(IF(DDPM!K6="","",DDPM!K6),"") -> Annual | G46: =IFERROR(IF(DDPM!A6="","",DDPM!L6&" / "&DDPM!M6),"") -> National / Province | H46: =IFERROR(IF(DDPM!A6="","",DDPM!N6&" / "&DDPM!O6),"") -> CSV / Restricted | I46: =IFERROR(IF(DDPM!P6="","",HYPERLINK(DDPM!P6,IF(LEN(DDPM!P6)>45,LEFT(DDPM!P6,42)&"...",DDPM!P6))),"") -> -
A47: =IFERROR(IF(DDPM!A7="","",DDPM!A7),"") -> DDPM_3_2 | B47: =IFERROR(IF(DDPM!B7="","",DDPM!B7),"") -> มูลค่าความเสียหายจากภัยแล้ง | C47: =IFERROR(IF(DDPM!A7="","",DDPM!C7&CHAR(10)&DDPM!D7&CHAR(10)&DDPM!E7),"") -> IMPACT (Backward-looking) Loss & Damage LOSS_DAMAGE_RECORD | D47: =IFERROR(IF(DDPM!F7="","",DDPM!F7),"") -> Drought (ภัยแล้ง) | E47: =IFERROR(IF(DDPM!I7="","",DDPM!I7),"") -> 1960-2014; 2015-2040; 2041-2060; 2061-2080; 2081-2100 | F47: =IFERROR(IF(DDPM!K7="","",DDPM!K7),"") -> Annual | G47: =IFERROR(IF(DDPM!A7="","",DDPM!L7&" / "&DDPM!M7),"") -> National / Province | H47: =IFERROR(IF(DDPM!A7="","",DDPM!N7&" / "&DDPM!O7),"") -> CSV / Restricted | I47: =IFERROR(IF(DDPM!P7="","",HYPERLINK(DDPM!P7,IF(LEN(DDPM!P7)>45,LEFT(DDPM!P7,42)&"...",DDPM!P7))),"") -> -
A48: =IFERROR(IF(DDPM!A8="","",DDPM!A8),"") -> DDPM_3_3 | B48: =IFERROR(IF(DDPM!B8="","",DDPM!B8),"") -> พื้นที่ประสบภัยน้ำท่วมรุนแรง | C48: =IFERROR(IF(DDPM!A8="","",DDPM!C8&CHAR(10)&DDPM!D8&CHAR(10)&DDPM!E8),"") -> Forward-looking Hazard HAZARDOUS_EVENT | D48: =IFERROR(IF(DDPM!F8="","",DDPM!F8),"") -> Flood (อุทกภัย) | E48: =IFERROR(IF(DDPM!I8="","",DDPM!I8),"") -> 1960-2014; 2015-2040; 2041-2060; 2061-2080; 2081-2100 | F48: =IFERROR(IF(DDPM!K8="","",DDPM!K8),"") -> Annual | G48: =IFERROR(IF(DDPM!A8="","",DDPM!L8&" / "&DDPM!M8),"") -> National / Province | H48: =IFERROR(IF(DDPM!A8="","",DDPM!N8&" / "&DDPM!O8),"") -> CSV / Restricted | I48: =IFERROR(IF(DDPM!P8="","",HYPERLINK(DDPM!P8,IF(LEN(DDPM!P8)>45,LEFT(DDPM!P8,42)&"...",DDPM!P8))),"") -> -
A49: =IFERROR(IF(DDPM!A9="","",DDPM!A9),"") -> DDPM_3_4 | B49: =IFERROR(IF(DDPM!B9="","",DDPM!B9),"") -> สัดส่วนหมู่บ้านและชุมชนที่ประสบภัยแล้งรุนแรง | C49: =IFERROR(IF(DDPM!A9="","",DDPM!C9&CHAR(10)&DDPM!D9&CHAR(10)&DDPM!E9),"") -> IMPACT (Backward-looking) Loss & Damage LOSS_DAMAGE_RECORD | D49: =IFERROR(IF(DDPM!F9="","",DDPM!F9),"") -> Flood (อุทกภัย) | E49: =IFERROR(IF(DDPM!I9="","",DDPM!I9),"") -> 1960-2014; 2015-2040; 2041-2060; 2061-2080; 2081-2100 | F49: =IFERROR(IF(DDPM!K9="","",DDPM!K9),"") -> Annual | G49: =IFERROR(IF(DDPM!A9="","",DDPM!L9&" / "&DDPM!M9),"") -> National / Province | H49: =IFERROR(IF(DDPM!A9="","",DDPM!N9&" / "&DDPM!O9),"") -> CSV / Restricted | I49: =IFERROR(IF(DDPM!P9="","",HYPERLINK(DDPM!P9,IF(LEN(DDPM!P9)>45,LEFT(DDPM!P9,42)&"...",DDPM!P9))),"") -> -
A50: =IFERROR(IF(DDPM!A10="","",DDPM!A10),"") -> DDPM_3_5 | B50: =IFERROR(IF(DDPM!B10="","",DDPM!B10),"") -> ระยะเวลาที่น้ำท่วมขัง ในเขตที่อยู่อาศัย | C50: =IFERROR(IF(DDPM!A10="","",DDPM!C10&CHAR(10)&DDPM!D10&CHAR(10)&DDPM!E10),"") -> IMPACT (Backward-looking) Loss & Damage LOSS_DAMAGE_RECORD | D50: =IFERROR(IF(DDPM!F10="","",DDPM!F10),"") -> Flood (อุทกภัย) | E50: =IFERROR(IF(DDPM!I10="","",DDPM!I10),"") -> 1960-2014; 2015-2040; 2041-2060; 2061-2080; 2081-2100 | F50: =IFERROR(IF(DDPM!K10="","",DDPM!K10),"") -> Annual | G50: =IFERROR(IF(DDPM!A10="","",DDPM!L10&" / "&DDPM!M10),"") -> National / Province | H50: =IFERROR(IF(DDPM!A10="","",DDPM!N10&" / "&DDPM!O10),"") -> CSV / Restricted | I50: =IFERROR(IF(DDPM!P10="","",HYPERLINK(DDPM!P10,IF(LEN(DDPM!P10)>45,LEFT(DDPM!P10,42)&"...",DDPM!P10))),"") -> -
A51: =IFERROR(IF(DDPM!A11="","",DDPM!A11),"") -> DDPM_3_6 | B51: =IFERROR(IF(DDPM!B11="","",DDPM!B11),"") -> ระดับความลึกของน้ำท่วม ในเขตที่อยู่อาศัย | C51: =IFERROR(IF(DDPM!A11="","",DDPM!C11&CHAR(10)&DDPM!D11&CHAR(10)&DDPM!E11),"") -> IMPACT (Backward-looking) Loss & Damage LOSS_DAMAGE_RECORD | D51: =IFERROR(IF(DDPM!F11="","",DDPM!F11),"") -> Flood (อุทกภัย) | E51: =IFERROR(IF(DDPM!I11="","",DDPM!I11),"") -> 1960-2014; 2015-2040; 2041-2060; 2061-2080; 2081-2100 | F51: =IFERROR(IF(DDPM!K11="","",DDPM!K11),"") -> Annual | G51: =IFERROR(IF(DDPM!A11="","",DDPM!L11&" / "&DDPM!M11),"") -> National / Province | H51: =IFERROR(IF(DDPM!A11="","",DDPM!N11&" / "&DDPM!O11),"") -> CSV / Restricted | I51: =IFERROR(IF(DDPM!P11="","",HYPERLINK(DDPM!P11,IF(LEN(DDPM!P11)>45,LEFT(DDPM!P11,42)&"...",DDPM!P11))),"") -> -
A52: =IFERROR(IF(DDPM!A12="","",DDPM!A12),"") -> DDPM_3_7 | B52: =IFERROR(IF(DDPM!B12="","",DDPM!B12),"") -> สัดส่วนหมู่บ้านและชุมชนที่มีอุทกภัย/ดินโคลนถล่ม (รวม — ต่อหมู่บ้านทั้งหมด) | C52: =IFERROR(IF(DDPM!A12="","",DDPM!C12&CHAR(10)&DDPM!D12&CHAR(10)&DDPM!E12),"") -> IMPACT (Backward-looking) Loss & Damage LOSS_DAMAGE_RECORD | D52: =IFERROR(IF(DDPM!F12="","",DDPM!F12),"") -> Drought (ภัยแล้ง) | E52: =IFERROR(IF(DDPM!I12="","",DDPM!I12),"") -> 1960-2014; 2015-2040; 2041-2060; 2061-2080; 2081-2100 | F52: =IFERROR(IF(DDPM!K12="","",DDPM!K12),"") -> Annual | G52: =IFERROR(IF(DDPM!A12="","",DDPM!L12&" / "&DDPM!M12),"") -> National / Province | H52: =IFERROR(IF(DDPM!A12="","",DDPM!N12&" / "&DDPM!O12),"") -> CSV / Restricted | I52: =IFERROR(IF(DDPM!P12="","",HYPERLINK(DDPM!P12,IF(LEN(DDPM!P12)>45,LEFT(DDPM!P12,42)&"...",DDPM!P12))),"") -> -
A53: =IFERROR(IF(DDPM!A13="","",DDPM!A13),"") -> DDPM_3_8 | B53: =IFERROR(IF(DDPM!B13="","",DDPM!B13),"") -> สัดส่วนหมู่บ้านและชุมชนที่มีอุทกภัย ดินโคลนถล่มต่อหมู่บ้านทั้งหมด | C53: =IFERROR(IF(DDPM!A13="","",DDPM!C13&CHAR(10)&DDPM!D13&CHAR(10)&DDPM!E13),"") -> IMPACT (Backward-looking) Loss & Damage LOSS_DAMAGE_RECORD | D53: =IFERROR(IF(DDPM!F13="","",DDPM!F13),"") -> Flood (อุทกภัย) | E53: =IFERROR(IF(DDPM!I13="","",DDPM!I13),"") -> 1960-2014; 2015-2040; 2041-2060; 2061-2080; 2081-2100 | F53: =IFERROR(IF(DDPM!K13="","",DDPM!K13),"") -> Annual | G53: =IFERROR(IF(DDPM!A13="","",DDPM!L13&" / "&DDPM!M13),"") -> National / Province | H53: =IFERROR(IF(DDPM!A13="","",DDPM!N13&" / "&DDPM!O13),"") -> CSV / Restricted | I53: =IFERROR(IF(DDPM!P13="","",HYPERLINK(DDPM!P13,IF(LEN(DDPM!P13)>45,LEFT(DDPM!P13,42)&"...",DDPM!P13))),"") -> -
... A56: =IFERROR(IF(DDPM!A16="","",DDPM!A16),"") -> DDPM_3_11 | B56: =IFERROR(IF(DDPM!B16="","",DDPM!B16),"") -> สัดส่วนหมู่บ้านและชุมชนที่มีอุทกภัย ดินโคลนถล่ม | C56: =IFERROR(IF(DDPM!A16="","",DDPM!C16&CHAR(10)&DDPM!D16&CHAR(10)&DDPM!E16),"") -> IMPACT (Backward-looking) Loss & Damage LOSS_DAMAGE_RECORD | D56: =IFERROR(IF(DDPM!F16="","",DDPM!F16),"") -> Flood (อุทกภัย) | E56: =IFERROR(IF(DDPM!I16="","",DDPM!I16),"") -> 1960-2014; 2015-2040; 2041-2060; 2061-2080; 2081-2100 | F56: =IFERROR(IF(DDPM!K16="","",DDPM!K16),"") -> Annual | G56: =IFERROR(IF(DDPM!A16="","",DDPM!L16&" / "&DDPM!M16),"") -> National / Province | H56: =IFERROR(IF(DDPM!A16="","",DDPM!N16&" / "&DDPM!O16),"") -> CSV / Restricted | I56: =IFERROR(IF(DDPM!P16="","",HYPERLINK(DDPM!P16,IF(LEN(DDPM!P16)>45,LEFT(DDPM!P16,42)&"...",DDPM!P16))),"") -> -
...

Sheet Introduction
B1: บัญชีรายการชุดข้อมูลพื้นฐาน
B2: Baseline Data Inventory
B4: 1. วัตถุประสงค์ (Purpose)
B5: ไฟล์นี้ใช้รวบรวมและจัดทำบัญชีรายการชุดข้อมูลพื้นฐานที่มีอยู่และถูกใช้งาน ณ ปัจจุบัน ตาม TOR ข้อ 5.3.5 จัดทำบัญชีรายการชุดข้อมูลพื้นฐาน (Baseline Data Inventory) โดยการรวบรวมและจัดทำ บัญชีรายการ "ชุดข้อมูลดิบ" ที่จำเป็นต่อการพัฒนาบริการสารสนเทศ ณ ปัจจุบัน โดยจัดหมวดหมู่ตามกรอบการประเมินความเสี่ยงที่เป็นมาตรฐานสากล และระบุรายละเอียดสำคัญของแต่ละรายการ ดังนี้ - ﻿﻿ตัวขับเคลื่อนภูมิอากาศ (Climatic Driver): ปัจจัยหลักที่มีอิทธิพลต่อสภาพอากาศและภัย - ﻿﻿ภัย (Hazard): ข้อมูลภัยพิบัติต่างๆ (อุทกภัย, ภัยแล้ง, คลื่นความร้อน ฯลฯ) - ﻿﻿การเปิดรับภัย (Exposure): ข้อมูลตำแหน่งและปริมาณของคน/ทรัพย์สินที่อาจได้รับผลกระทบ - ความอ่อนไหวต่อภัย (Sensitivity): ข้อมูลคุณลักษณะของระบบ/ประชากรที่ได้รับผลกระทบได้ง่าย - ความสามารถในการปรับตัว (Adaptive Capacity): ข้อมูลศักยภาพเชิงกายภาพ, เศรษฐกิจ,และสังคมในการรับมือ - ผลกระทบ (Impact): ข้อมูลความเสียหายและความสูญเสียที่เกิดขึ้น - การตอบสนอง (Response): ข้อมูลมาตรการที่ใช้เพื่อจัดการความเสี่ยง - ความสูญเสียและความเสียหายจากการเปลี่ยนแปลงสภาพภูมิอากาศของประเทศไทย โดยแต่ละชุดข้อมูลให้ระบุรายละเอียดสำคัญ เช่น แหล่งที่มา, ขอบเขต, ปี, ความละเอียด, ข้อจำกัด, และระบุว่าเป็นข้อมูลในอดีต (Historical) หรือข้อมูลคาดการณ์ในอนาคต (Projected)
B7: 2. โครงสร้างไฟล์ (File Structure)
B8: Sheet | C8: คำอธิบาย (Description)
B9: Introduction | C9: คำอธิบายภาพรวม นิยามคอลัมน์ และรหัส
B10: Datasets_v1.0 | C10: ชุดข้อมูลแต่ละรายการ โดย 1 แถว รวมหมวดความเสี่ยง ภัย และสาขา
B11: Ref_Lookups | C11: รายการ dropdown และคำศัพท์ทั้งหมด
B13: 3. นิยามคอลัมน์ (Column Definitions)
B14: Column | C14: คำอธิบาย (Description)
B15: Source_ID | C15: รหัสอ้างอิงแหล่งที่มาของข้อมูล กำหนดจากตัวย่อหน่วยงานตามด้วยลำดับที่
B16: Source_Agency_TH | C16: ชื่อหน่วยงานเจ้าของข้อมูลเป็นภาษาไทยอย่างเป็นทางการ
B17: Source_Agency_Abrv | C17: ตัวย่อชื่อหน่วยงานเจ้าของข้อมูลตามที่ใช้อย่างเป็นทางการ
B18: Source_Name | C18: ชื่อระบบหรือฐานข้อมูลต้นทางที่เผยแพร่ชุดข้อมูล
B19: Source_Type | C19: ประเภทของแหล่งที่มา เช่น ฐานข้อมูลภาครัฐ ระบบสารสนเทศภูมิศาสตร์ หรือรายงาน
B20: Access_Level | C20: ระดับการเข้าถึงแหล่งข้อมูลโดยรวม โดย Open แปลว่า เข้าถึงได้เอง Restricted แปลว่า ต้องมีการขอข้อมูล
B21: URL (Source) | C21: ที่อยู่อินเทอร์เน็ตของแหล่งข้อมูลต้นทาง
B22: Remarks (Source) | C22: หมายเหตุเพิ่มเติมเกี่ยวกับแหล่งที่มา
B23: Dataset ID | C23: รหัสประจำชุดข้อมูล ใช้เพื่อการอ้างอิงภายในระบบ
B24: Dataset Name (Thai) | C24: ชื่อชุดข้อมูลเป็นภาษาไทย
B25: Domain | C25: ขอบข่ายของข้อมูลตามกรอบการดำเนินงานด้านการเปลี่ยนแปลงสภาพภูมิอากาศ
... B38: Remarks | C38: หมายเหตุเพิ่มเติมเกี่ยวกับชุดข้อมูล
B40: 4. โครงสร้างข้อมูล (Data Structure)
B41: คำอธิบาย (Description) | C41: Structure
B42: โครงสร้างถูกอ้างอิงตาม Conceptual Data Model (CDM) สำหรับการพัฒนา National Climate Adaptation Information Framework (NCAIF) | C42: Data Structure │ ├─ [1. Forward-looking] │ ├─ [Hazard] │ │ ├─ HAZARDOUS_EVENT │ │ ├─ HAZARD_MAP │ │ ├─ SATELLITE_OBSERVATION │ │ ├─ METEOROLOGICAL_OBSERVATION │ │ ├─ TOPOGRAPHY │ │ └─ ENVIRONMENT │ │ │ ├─ [Exposure] │ │ └─ EXPOSED_ASSET │ │ │ ├─ [Vulnerability] │ │ └─ VULNERABILITY_FRAMEWORK │ │ ├─ SENSITIVITY │ │ └─ ADAPTIVE_CAPACITY │ │ │ ├─ [CLIMATE_DRIVER] │ │ │ ├─ [COMPOSITE_INDEX] │ │ │ └─ [RISK_METRIC] │ ├─ [2. IMPACT (Backward-looking)] │ ├─ DISASTER_RECORD │ └─ LOSS_DAMAGE_RECORD │ ├─ [3. Adaptation Planning] │ └─ RESPONSE │ └─ [4. SPATIAL_UNIT]

Sheet Datasets_ฺmain_backup
A1: รหัสแหล่งที่มา Source_ID | B1: หน่วยงานแหล่งที่มา Source_Agency_TH | C1: ตัวย่อหน่วยงานแหล่งที่มา Source_Agency_Abrv | D1: ชื่อแหล่งที่มา Source_Name | E1: ประเภทแหล่งที่มา Source_Type | F1: ระดับการเข้าถึง Access_Level | G1: URL | H1: หมายเหตุ Remarks
A2: BMA_1 | B2: กรุงเทพมหานคร | C2: BMA | D2: ข้อมูลจากการสัมภาษณ์ | E2: Interview | F2: Restricted | G2: -
A3: CDD_1 | B3: กรมการพัฒนาชุมชน | C3: CDD | F3: Restricted | G3: - | H3: ข้อมูลจำนวนและการกระจายตัวของครัวเรือนกลุ่มเปราะบาง (ยากจน ผู้สูงอายุ ผู้พิการ ฯลฯ) | จากรายการขอข้อมูล WebGIS DCCE 19/01/2026 (1_Data_WebGIS_DCCE_20260119.xlsx → sheet: CDD, ลำดับที่ 1)
A4: DCCE_1 | B4: กรมการเปลี่ยนแปลงสภาพภูมิอากาศและสิ่งแวดล้อม | C4: DCCE | D4: Report รายงานฉบับสมบูรณ์โครงการปรับปรุงระบบฐานข้อมูลความเสี่ยงเชิงพื้นที่จากการเปลี่ยนแปลงสภาพภูมิอากาศ | E4: Report | F4: Restricted | G4: -
A5: DCCE_2 | B5: กรมการเปลี่ยนแปลงสภาพภูมิอากาศและสิ่งแวดล้อม | C5: DCCE | D5: Website Climate Data Visualization | E5: Website | F5: Restricted | G5: https://clim-webbased.dcce.go.th/DataServices
A6: DCCE_3 | B6: กรมการเปลี่ยนแปลงสภาพภูมิอากาศและสิ่งแวดล้อม | C6: DCCE | D6: Website ฐานข้อมูลความเสี่ยงจากการเปลี่ยนแปลงสภาพภูมิอากาศ | E6: Website | F6: Open | G6: https://ccic.dcce.go.th/riskarea
A7: DDPM_1 | B7: กรมป้องกันและบรรเทาสาธารณภัย | C7: DDPM | F7: Restricted | G7: - | H7: ข้อมูลแผนที่แสดงระดับความเสี่ยงอุทกภัยในพื้นที่ | จากรายการขอข้อมูล WebGIS DCCE 19/01/2026 (1_Data_WebGIS_DCCE_20260119.xlsx → sheet: DDPM, ลำดับที่ 1)
A8: DDPM_2 | B8: กรมป้องกันและบรรเทาสาธารณภัย | C8: DDPM | D8: ข้อมูลจากการสัมภาษณ์ | E8: Interview | F8: Restricted | G8: -
A9: DGA_1 | B9: สำนักงานพัฒนารัฐบาลดิจิทัล (องค์การมหาชน) | C9: DGA | D9: ข้อมูลจากการสัมภาษณ์ | E9: Interview | F9: Restricted | G9: -
A10: DLA_1 | B10: กรมส่งเสริมการปกครองท้องถิ่น | C10: DLA | D10: ข้อมูลจากการสัมภาษณ์ | E10: Interview | F10: Restricted | G10: -
A11: DMCR_5 | B11: กรมทรัพยากรทางทะเลและชายฝั่ง | C11: DMCR | D11: Website THAILAND COASTAL SPATIAL DATABASE SYSTEM ระบบฐานข้อมูลเชิงพื้นที่การเปลี่ยนแปลงพื้นที่ชายฝั่งทะเลไทย | E11: Website | F11: Open | G11: https://tcs.dmcr.go.th/dmcr/v2/router?page=dashboard
A12: DMCR_6 | B12: กรมทรัพยากรทางทะเลและชายฝั่ง | C12: DMCR | D12: Website GEO-INFORMATICS DATA CENTER FOR MARINE AND COASTAL ศูนย์ข้อมูลภูมิสารสนเทศทางทะเลและชายฝั่ง | E12: Website | F12: Open | G12: https://marinemap.dmcr.go.th/
A13: DMCR_7 | B13: กรมทรัพยากรทางทะเลและชายฝั่ง | C13: DMCR | D13: Website Project to develop a system for assessing coral bleaching โครงการพัฒนาระบบประเมินการเกิดปะการังฟอกขาว | E13: Website | F13: Open | G13: https://thailandcoralbleaching.dmcr.go.th/th/home#coral-report-scroll
A14: DMR_1 | B14: กรมทรัพยากรธรณี | C14: DMR | F14: Restricted | G14: - | H14: ข้อมูลพื้นที่ที่ได้รับผลกระทบจริงจากเหตุแผ่นดินถล่ม น้ำป่าไหลหลาก และน้ำท่วมฉับพลัน | จากรายการขอข้อมูล WebGIS DCCE 19/01/2026 (1_Data_WebGIS_DCCE_20260119.xlsx → sheet: DMR, ลำดับที่ 1)
A15: DMR_2 | B15: กรมทรัพยากรธรณี | C15: DMR | D15: Website GD Catalog พื้นที่ได้รับผลกระทบจากแผ่นดินถล่มและน้ำป่าไหลหลาก | E15: Website | F15: Open | G15: https://gdcatalog.go.th/dataset/gdpublish-debris_flood
A16: DOH_1 | B16: กรมทางหลวง | C16: DOH | F16: Restricted | G16: - | H16: ข้อมูลแนวเส้นถนนหลวง ถนนสายหลัก และทางหลวงพิเศษ | จากรายการขอข้อมูล WebGIS DCCE 19/01/2026 (1_Data_WebGIS_DCCE_20260119.xlsx → sheet: DOH, ลำดับที่ 1)
A17: DOHealth_1 | B17: กรมอนามัย | C17: DOHealth | F17: Restricted | G17: - | H17: ข้อมูลตำแหน่งที่ตั้งของโรงพยาบาลและศูนย์สุขภาพประจำตำบล (รพ.สต.) | จากรายการขอข้อมูล WebGIS DCCE 19/01/2026 (1_Data_WebGIS_DCCE_20260119.xlsx → sheet: DOHealth, ลำดับที่ 1)
A18: DOPA_1 | B18: กรมการปกครอง | C18: DOPA | D18: Website กรมการปกครอง | E18: Website | F18: Restricted | G18: https://www.dopa.go.th/
A19: DOT_1 | B19: กรมการท่องเที่ยว | C19: DOT | F19: Restricted | G19: - | H19: ข้อมูลตำแหน่งและขอบเขตของแหล่งท่องเที่ยวธรรมชาติ วัฒนธรรม ชุมชน นิเวศ และนันทนาการ | จากรายการขอข้อมูล WebGIS DCCE 19/01/2026 (1_Data_WebGIS_DCCE_20260119.xlsx → sheet: DOT, ลำดับที่ 1)
A20: DPT_1 | B20: กรมโยธาธิการและผังเมือง | C20: DPT | D20: ข้อมูลจากการสัมภาษณ์ | E20: Interview | F20: Restricted | G20: -
A21: EPPO_1 | B21: สำนักงานนโยบายและแผนพลังงาน | C21: EPPO | F21: Restricted | G21: https://www2.eppo.go.th/cdf/data_regional_central.html
A22: FAD_1 | B22: กรมศิลปากร | C22: FAD | F22: Restricted | G22: - | H22: ข้อมูลตำแหน่งและขอบเขตของแหล่งโบราณสถานในความรับผิดชอบของกรมศิลปากร | จากรายการขอข้อมูล WebGIS DCCE 19/01/2026 (1_Data_WebGIS_DCCE_20260119.xlsx → sheet: FAD, ลำดับที่ 1)
A23: FTI_1 | B23: สภาอุตสาหกรรมแห่งประเทศไทย | C23: FTI | D23: ข้อมูลจากการสัมภาษณ์ | E23: Interview | F23: Restricted | G23: -
A24: GISTDA_1 | B24: สำนักงานพัฒนาเทคโนโลยีอวกาศและภูมิสารสนเทศ (องค์การมหาชน) | C24: GISTDA | D24: Website Gistda Gateway | E24: Website | F24: Open | G24: https://api-gateway.gistda.or.th/
A25: GISTDA_2 | B25: สำนักงานพัฒนาเทคโนโลยีอวกาศและภูมิสารสนเทศ (องค์การมหาชน) | C25: GISTDA | D25: Website Marine GI Portal ระบบประเมินและติดตามระบบนิเวศทางทะเลและชายฝั่ง | E25: Website | F25: Open | G25: https://portal.marineportal.gistda.or.th/catalogue/#/
A26: GISTDA_3 | B26: สำนักงานพัฒนาเทคโนโลยีอวกาศและภูมิสารสนเทศ (องค์การมหาชน) | C26: GISTDA | D26: Website Disaster Platform ระบบสนับสนุนการตัดสินใจเพื่อบริหารจัดการภัยพิบัติ | E26: Website | F26: Open | G26: https://disaster.gistda.or.th/services/download
A27: GISTDA_4 | B27: สำนักงานพัฒนาเทคโนโลยีอวกาศและภูมิสารสนเทศ (องค์การมหาชน) | C27: GISTDA | D27: Website GISTDA DATA CUBE | E27: Website | F27: Open | G27: https://datacube.gistda.or.th/
A28: HII_1 | B28: สถาบันสารสนเทศทรัพยากรน้ำ (องค์การมหาชน) | C28: HII | F28: Restricted | G28: - | H28: ข้อมูลพื้นที่เสี่ยงภัยแล้งที่ได้จากการประเมินด้วยดัชนี Drought Risk Index (DRI) | จากรายการขอข้อมูล WebGIS DCCE 19/01/2026 (1_Data_WebGIS_DCCE_20260119.xlsx → sheet: HII, ลำดับที่ 1)
A29: IEAT_1 | B29: การนิคมอุตสาหกรรมแห่งประเทศไทย | C29: IEAT | F29: Restricted | G29: - | H29: ข้อมูลตำแหน่งที่ตั้งและขอบเขตของเขตนิคมอุตสาหกรรม | จากรายการขอข้อมูล WebGIS DCCE 19/01/2026 (1_Data_WebGIS_DCCE_20260119.xlsx → sheet: IEAT, ลำดับที่ 1)
A30: LDD_1 | B30: กรมพัฒนาที่ดิน | C30: LDD | F30: Restricted | G30: - | H30: ข้อมูลพื้นที่ที่เกิดภาวะแล้งซ้ำซากอย่างต่อเนื่อง | จากรายการขอข้อมูล WebGIS DCCE 19/01/2026 (1_Data_WebGIS_DCCE_20260119.xlsx → sheet: LDD, ลำดับที่ 1)
A31: LDD_4 | B31: กรมพัฒนาที่ดิน | C31: LDD | D31: Website บัญชีรายการข้อมูลกรมพัฒนาที่ดิน พื้นที่เสี่ยงภัย | E31: Website | F31: Restricted | G31: http://sql.ldd.go.th/ldddata/mapsoilH3.html
A32: MD_1 | B32: กรมเจ้าท่า | C32: MD | F32: Restricted | G32: - | H32: ข้อมูลระดับน้ำทะเลบริเวณอ่าวไทย และฝั่งอันดามัน | จากรายการขอข้อมูล WebGIS DCCE 19/01/2026 (1_Data_WebGIS_DCCE_20260119.xlsx → sheet: MD, ลำดับที่ 1)
A33: MD_2 | B33: กรมเจ้าท่า | C33: MD | D33: Website กลุ่มอุทกวิทยา กรมเจ้าท่า | E33: Website | F33: Open | G33: http://hydro.md.go.th/
A34: MHESI_1 | B34: กระทรวงการอุดมศึกษา วิทยาศาสตร์ วิจัยและนวัตกรรม | C34: MHESI | F34: Restricted | G34: - | H34: ข้อมูลตำแหน่งที่ตั้งและขอบเขตของสถาบันอุดมศึกษา | จากรายการขอข้อมูล WebGIS DCCE 19/01/2026 (1_Data_WebGIS_DCCE_20260119.xlsx → sheet: MHESI, ลำดับที่ 1)
A35: MSDHS_1 | B35: กระทรวงการพัฒนาสังคมและความมั่นคงของมนุษย์ | C35: MSDHS | D35: ข้อมูลจากการสัมภาษณ์ | E35: Interview | F35: Restricted | G35: -
A36: MWA_1 | B36: การประปานครหลวง | C36: MWA | F36: Restricted | G36: - | H36: ข้อมูลตำแหน่งที่ตั้งและขอบเขตของโรงประปานครหลวง | จากรายการขอข้อมูล WebGIS DCCE 19/01/2026 (1_Data_WebGIS_DCCE_20260119.xlsx → sheet: MWA, ลำดับที่ 1)
A37: NESDC_1 | B37: สำนักงานสภาพัฒนาการเศรษฐกิจและสังคมแห่งชาติ | C37: NESDC | D37: ข้อมูลจากการสัมภาษณ์ | E37: Interview | F37: Restricted | G37: -
A38: NSO_1 | B38: สำนักงานสถิติแห่งชาติ | C38: NSO | D38: Website สำรวจข้อมูลพื้นฐานของครัวเรือน | E38: Website | F38: Restricted | G38: https://www.nso.go.th/nsoweb/nso/survey_detail/nj#gsc.tab=0
A39: NSO_2 | B39: สำนักงานสถิติแห่งชาติ | C39: NSO | D39: ข้อมูลจากการสัมภาษณ์ | E39: Interview | F39: Restricted | G39: -
A40: NXPO_1 | B40: สำนักงานสภานโยบายการอุดมศึกษา วิทยาศาสตร์ วิจัยและนวัตกรรมแห่งชาติ | C40: NXPO | D40: ข้อมูลจากการสัมภาษณ์ | E40: Interview | F40: Restricted | G40: -
...

Sheet Datasets_main
A1: ตัวย่อหน่วยงาน Agency_Abrv | B1: ชื่อหน่วยงาน Agency_Name | C1: ลิงก์ไปยังชีต Go to Sheet
A2: BMA | B2: กรุงเทพมหานคร | C2: =HYPERLINK("#'BMA'!A1","ไปที่ชีต BMA →") -> ไปที่ชีต BMA →
A3: CDD | B3: กรมการพัฒนาชุมชน | C3: =HYPERLINK("#'CDD'!A1","ไปที่ชีต CDD →") -> ไปที่ชีต CDD →
A4: DCCE | B4: กรมการเปลี่ยนแปลงสภาพภูมิอากาศและสิ่งแวดล้อม | C4: =HYPERLINK("#'DCCE'!A1","ไปที่ชีต DCCE →") -> ไปที่ชีต DCCE →
A5: DDPM | B5: กรมป้องกันและบรรเทาสาธารณภัย | C5: =HYPERLINK("#'DDPM'!A1","ไปที่ชีต DDPM →") -> ไปที่ชีต DDPM →
A6: DMCR | B6: กรมทรัพยากรทางทะเลและชายฝั่ง | C6: =HYPERLINK("#'DMCR'!A1","ไปที่ชีต DMCR →") -> ไปที่ชีต DMCR →
A7: DMR | B7: กรมทรัพยากรธรณี | C7: =HYPERLINK("#'DMR'!A1","ไปที่ชีต DMR →") -> ไปที่ชีต DMR →
A8: DOH | B8: กรมทางหลวง | C8: =HYPERLINK("#'DOH'!A1","ไปที่ชีต DOH →") -> ไปที่ชีต DOH →
A9: DOHealth | B9: กรมอนามัย | C9: =HYPERLINK("#'DOHealth'!A1","ไปที่ชีต DOHealth →") -> ไปที่ชีต DOHealth →
A10: DOPA | B10: กรมการปกครอง | C10: =HYPERLINK("#'DOPA'!A1","ไปที่ชีต DOPA →") -> ไปที่ชีต DOPA →
A11: DOT | B11: กรมการท่องเที่ยว | C11: =HYPERLINK("#'DOT'!A1","ไปที่ชีต DOT →") -> ไปที่ชีต DOT →
A12: DPT | B12: กรมโยธาธิการและผังเมือง | C12: =HYPERLINK("#'DPT'!A1","ไปที่ชีต DPT →") -> ไปที่ชีต DPT →
A13: DWR | B13: กรมทรัพยากรน้ำ | C13: =HYPERLINK("#'DWR'!A1","ไปที่ชีต DWR →") -> ไปที่ชีต DWR →
A14: EPPO | B14: สำนักงานนโยบายและแผนพลังงาน | C14: =HYPERLINK("#'EPPO'!A1","ไปที่ชีต EPPO →") -> ไปที่ชีต EPPO →
A15: FAD | B15: กรมศิลปากร | C15: =HYPERLINK("#'FAD'!A1","ไปที่ชีต FAD →") -> ไปที่ชีต FAD →
A16: FTI | B16: สภาอุตสาหกรรมแห่งประเทศไทย | C16: =HYPERLINK("#'FTI'!A1","ไปที่ชีต FTI →") -> ไปที่ชีต FTI →
A17: GISTDA | B17: สำนักงานพัฒนาเทคโนโลยีอวกาศและภูมิสารสนเทศ (องค์การมหาชน) | C17: =HYPERLINK("#'GISTDA'!A1","ไปที่ชีต GISTDA →") -> ไปที่ชีต GISTDA →
A18: HII | B18: สถาบันสารสนเทศทรัพยากรน้ำ (องค์การมหาชน) | C18: =HYPERLINK("#'HII'!A1","ไปที่ชีต HII →") -> ไปที่ชีต HII →
A19: IEAT | B19: การนิคมอุตสาหกรรมแห่งประเทศไทย | C19: =HYPERLINK("#'IEAT'!A1","ไปที่ชีต IEAT →") -> ไปที่ชีต IEAT →
A20: LDD | B20: กรมพัฒนาที่ดิน | C20: =HYPERLINK("#'LDD'!A1","ไปที่ชีต LDD →") -> ไปที่ชีต LDD →
A21: MD | B21: กรมเจ้าท่า | C21: =HYPERLINK("#'MD'!A1","ไปที่ชีต MD →") -> ไปที่ชีต MD →
A22: MHESI | B22: กระทรวงการอุดมศึกษา วิทยาศาสตร์ วิจัยและนวัตกรรม | C22: =HYPERLINK("#'MHESI'!A1","ไปที่ชีต MHESI →") -> ไปที่ชีต MHESI →
A23: MSDHS | B23: กระทรวงการพัฒนาสังคมและความมั่นคงของมนุษย์ | C23: =HYPERLINK("#'MSDHS'!A1","ไปที่ชีต MSDHS →") -> ไปที่ชีต MSDHS →
A24: MWA | B24: การประปานครหลวง | C24: =HYPERLINK("#'MWA'!A1","ไปที่ชีต MWA →") -> ไปที่ชีต MWA →
A25: MoPH | B25: กระทรวงสาธารณสุข | C25: =HYPERLINK("#'MoPH'!A1","ไปที่ชีต MoPH →") -> ไปที่ชีต MoPH →
A26: NESDC | B26: สำนักงานสภาพัฒนาการเศรษฐกิจและสังคมแห่งชาติ | C26: =HYPERLINK("#'NESDC'!A1","ไปที่ชีต NESDC →") -> ไปที่ชีต NESDC →
A27: NSO | B27: สำนักงานสถิติแห่งชาติ | C27: =HYPERLINK("#'NSO'!A1","ไปที่ชีต NSO →") -> ไปที่ชีต NSO →
A28: OBEC | B28: สำนักงานคณะกรรมการการศึกษาขั้นพื้นฐาน | C28: =HYPERLINK("#'OBEC'!A1","ไปที่ชีต OBEC →") -> ไปที่ชีต OBEC →
A29: ONEP | B29: สำนักงานนโยบายและแผนทรัพยากรธรรมชาติและสิ่งแวดล้อม | C29: =HYPERLINK("#'ONEP'!A1","ไปที่ชีต ONEP →") -> ไปที่ชีต ONEP →
A30: OTP | B30: สำนักงานนโยบายและแผนการขนส่งและจราจร | C30: =HYPERLINK("#'OTP'!A1","ไปที่ชีต OTP →") -> ไปที่ชีต OTP →
A31: PWA | B31: การประปาส่วนภูมิภาค | C31: =HYPERLINK("#'PWA'!A1","ไปที่ชีต PWA →") -> ไปที่ชีต PWA →
A32: SRT | B32: การรถไฟแห่งประเทศไทย | C32: =HYPERLINK("#'SRT'!A1","ไปที่ชีต SRT →") -> ไปที่ชีต SRT →
A33: TMD | B33: กรมอุตุนิยมวิทยา | C33: =HYPERLINK("#'TMD'!A1","ไปที่ชีต TMD →") -> ไปที่ชีต TMD →
A34: UDDC | B34: ศูนย์ออกแบบและพัฒนาเมือง | C34: =HYPERLINK("#'UDDC'!A1","ไปที่ชีต UDDC →") -> ไปที่ชีต UDDC →

Sheet Ref_Lookups
A1: ขอบข่ายข้อมูล | B1: ขอบข่ายข้อมูลย่อย | C1: ชื่อประเภทข้อมูล | D1: คำอธิบาย | F1: ภัยที่เกี่ยวข้อง | G1: สาขา | H1: มิติด้านเวลา | I1: ความละเอียดเชิงเวลา | J1: ขอบเขตเชิงพื้นที่ | K1: รูปแบบไฟล์ | L1: ระดับการเข้าถึง
A2: Domain | B2: Sub_Domain | C2: Data_Entity | D2: Description | F2: Related Hazards | G2: Sectors | H2: Temporal Dimension | I2: Temporal Resolution | J2: Spatial Scope | K2: Format | L2: Access_Level
A3: Forward-looking | B3: Hazard | C3: HAZARDOUS_EVENT | D3: บันทึกเหตุการณ์ภัยเชิงเวลา-พื้นที่ (track / footprint / intensity ของ event ที่เกิดขึ้น) ใช้สอบเทียบ hazard model | F3: Air Quality / Haze (คุณภาพอากาศ / หมอกควัน) | G3: Agriculture (เกษตร) | H3: Historical | I3: Real-time | J3: Global | K3: API / Web Service | L3: Open Access
A4: Forward-looking | B4: Hazard | C4: HAZARD_MAP | D4: แผนที่ภัย / ระดับความรุนแรง (probabilistic หรือ scenario-based zonation เช่น flood return period, landslide susceptibility) | F4: Coastal Erosion (กัดเซาะชายฝั่ง) | G4: Human Settlement (ตั้งถิ่นฐาน) | H4: Projected | I4: Sub-daily | J4: Regional | K4: CSV | L4: Restricted Access
A5: Forward-looking | B5: Hazard | C5: SATELLITE_OBSERVATION | D5: ข้อมูลสำรวจระยะไกล (flood extent, drought, NDVI, LST) สำหรับวิเคราะห์ภัย | F5: Cross-cutting (ทุกภัย) | G5: Natural Resources (ทรัพยากรธรรมชาติ) | H5: Forecast | I5: Daily | J5: National | K5: Database
A6: Forward-looking | B6: Hazard | C6: METEOROLOGICAL_OBSERVATION | D6: ข้อมูลตรวจวัดอุตุนิยมวิทยา (สถานี / เรดาร์ / reanalysis) | F6: Drought (ภัยแล้ง) | G6: Public Health (สาธารณสุข) | I6: Monthly | J6: Sub-national | K6: GeoTIFF / Raster
A7: Forward-looking | B7: Hazard | C7: TOPOGRAPHY | D7: ข้อมูลภูมิประเทศ-ธรณี (DEM, slope, soil, geology) ใช้ประกอบการประเมินภัย | F7: Flood (อุทกภัย) | G7: Tourism (ท่องเที่ยว) | I7: Seasonal | J7: Province | K7: NetCDF
A8: Forward-looking | B8: Hazard | C8: ENVIRONMENT | D8: ข้อมูลสิ่งแวดล้อมพื้นฐาน (land use / land cover, ecosystem, vegetation) | F8: Heat (คลื่นความร้อน) | G8: Water (น้ำ) | I8: Annual | J8: District | K8: Other
A9: Forward-looking | B9: Exposure | C9: EXPOSED_ASSET | D9: สินทรัพย์ / ประชากร / พื้นที่ที่อาจได้รับผลกระทบจากภัย | F9: Landslide (ดินถล่ม) | G9: Cross-cutting (หลายสาขา) | I9: Event-based | J9: Tambon | K9: PDF Report
A10: Forward-looking | B10: Vulnerability | C10: VULNERABILITY_FRAMEWORK | D10: กรอบประเมินความเปราะบาง (wrapper ของ Sensitivity + Adaptive Capacity) | F10: Sea-level Rise (ระดับน้ำทะเลสูงขึ้น) | I10: Biannual | J10: Mooban | K10: Shapefile
A11: Forward-looking | B11: Vulnerability | C11: SENSITIVITY | D11: คุณลักษณะที่ทำให้ระบบเปราะบาง (sensitivity factors) | F11: Storm (พายุ) | I11: Bi-weekly | J11: Basin | K11: Image
A12: Forward-looking | B12: Vulnerability | C12: ADAPTIVE_CAPACITY | D12: ศักยภาพในการรับมือ / ปรับตัวของระบบ | F12: Wildfire (ไฟป่า) | J12: Point | K12: GeoJSON
A13: Forward-looking | B13: Climate Driver | C13: CLIMATE_DRIVER | D13: ปัจจัยขับเคลื่อนภูมิอากาศ (T, P, wind, SLR) ทั้ง observed และ projection (RCP/SSP)
A14: Forward-looking | B14: Composite Index | C14: COMPOSITE_INDEX | D14: ดัชนีรวมจาก H × E × V (normative composite score สำหรับ screening / ranking)
A15: Forward-looking | B15: Risk Metric | C15: RISK_METRIC | D15: ตัวชี้วัดความเสี่ยงเชิงปริมาณ (probabilistic / monetized: AAL, PML, EAD)
A16: IMPACT (Backward-looking) | B16: Disaster Record | C16: DISASTER_RECORD | D16: บันทึกเหตุการณ์ภัยพิบัติในอดีต (DesInventar / Sigma) ใช้ calibrate hazard model และวิเคราะห์ impact
A17: IMPACT (Backward-looking) | B17: Loss & Damage | C17: LOSS_DAMAGE_RECORD | D17: บันทึกความสูญเสีย / เสียหายจริง (lives, assets, ecosystem services)
A18: Adaptation Planning | B18: Response | C18: RESPONSE | D18: มาตรการ / นโยบาย / โครงการ ที่ใช้จัดการความเสี่ยง (adaptation actions, M&E)
A19: Spatial Unit | B19: Spatial Unit | C19: SPATIAL_UNIT | D19: ขอบเขตการปกครอง / หน่วยวิเคราะห์เชิงพื้นที่ (province / district / tambon / mooban / basin)

Sheet DCCE
A1: รหัส Dataset ID | B1: ชื่อชุดข้อมูล (TH) Dataset Name (Thai) | C1: ขอบข่ายข้อมูล Domain | D1: ขอบข่ายข้อมูลย่อย Sub_Domain | E1: ชื่อประเภทข้อมูล Data_Entity | F1: ภัยที่เกี่ยวข้อง Related Hazards | G1: สาขา Sectors | H1: มิติด้านเวลา Temporal Dimension | I1: ช่วงเวลา Time Period | J1: หน่วย Unit | K1: ความละเอียดเชิงเวลา Temporal Resolution | L1: ขอบเขตเชิงพื้นที่ Spatial Scope | M1: ความละเอียดเชิงพื้นที่ Spatial Resolution | N1: รูปแบบไฟล์ Format | O1: ระดับการเข้าถึง Access_Level | P1: URL | Q1: ข้อจำกัด Limitations / Gaps | R1: หมายเหตุ Remarks | S1: ชื่อแหล่งที่มา Source_Name | T1: ประเภทแหล่งที่มา Source_Type | U1: ระดับการเข้าถึง Access_Level | V1: หมายเหตุ Remarks
A2: DCCE_2_1 | B2: ปริมาณน้ำฝน (GridData, historical) | C2: Forward-looking | D2: Climate Driver | E2: CLIMATE_DRIVER | F2: Drought (ภัยแล้ง) | G2: Cross-cutting (หลายสาขา) | H2: Historical | I2: 1981-2023 | J2: mm | K2: Daily; Monthly | L2: National | M2: 25 km (Grid) | N2: NetCDF | O2: Restricted | P2: https://clim-webbased.dcce.go.th/DataServices | Q2: - | R2: Model/Source: GridData · Variable: pr · Scenario: historical | S2: Website Climate Data Visualization | T2: Website | U2: Restricted
A3: DCCE_2_10 | B3: ความชื้นสัมพัทธ์ (WRF-Chem) | C3: Forward-looking | D3: Climate Driver | E3: CLIMATE_DRIVER | F3: ภัยแล้ง (Drought); ไฟป่า (Wildfire) | G3: Cross-cutting (หลายสาขา) | H3: Historical; Projected | I3: 1981-2014 (historical); 2015-2099 (ssp585) | J3: % | K3: Daily; Monthly | L3: National | M3: 25 km (Grid) | N3: NetCDF | O3: Restricted | P3: https://clim-webbased.dcce.go.th/DataServices | Q3: มีเฉพาะ ssp585 | R3: Model/Source: WRF-Chem · Variable: hurs | S3: Website Climate Data Visualization | T3: Website | U3: Restricted
A4: DCCE_2_11 | B4: ปริมาณน้ำฝน (RegCM5, EC-Earth3-Veg) | C4: Forward-looking | D4: Climate Driver | E4: CLIMATE_DRIVER | F4: น้ำท่วม (Flood); ภัยแล้ง (Drought) | G4: Cross-cutting (หลายสาขา) | H4: Historical; Projected | I4: 1960-2014 (historical); 2015-2099 (ssp245); 2015-2099 (ssp585) | J4: mm | K4: Daily; Monthly | L4: National | M4: 25 km (Grid) | N4: NetCDF | O4: Restricted | P4: https://clim-webbased.dcce.go.th/DataServices | Q4: - | R4: Model/Source: RegCM5(Driving Model: EC-Earth3-Veg) · Variable: pr | S4: Website Climate Data Visualization | T4: Website | U4: Restricted
A5: DCCE_2_12 | B5: อุณหภูมิสูงสุด (RegCM5, EC-Earth3-Veg) | C5: Forward-looking | D5: Climate Driver | E5: CLIMATE_DRIVER | F5: คลื่นความร้อน (Heat); ภัยแล้ง (Drought) | G5: Cross-cutting (หลายสาขา) | H5: Historical; Projected | I5: 1960-2014 (historical); 2015-2099 (ssp245); 2015-2099 (ssp585) | J5: °C | K5: Daily; Monthly | L5: National | M5: 25 km (Grid) | N5: NetCDF | O5: Restricted | P5: https://clim-webbased.dcce.go.th/DataServices | Q5: - | R5: Model/Source: RegCM5 (EC-Earth3-Veg) · Variable: tasmax | S5: Website Climate Data Visualization | T5: Website | U5: Restricted
A6: DCCE_2_13 | B6: อุณหภูมิต่ำสุด (RegCM5, EC-Earth3-Veg) | C6: Forward-looking | D6: Climate Driver | E6: CLIMATE_DRIVER | F6: คลื่นความเย็น (Cold spell); คลื่นความร้อน (Heat) | G6: Cross-cutting (หลายสาขา) | H6: Historical; Projected | I6: 1960-2014 (historical); 2015-2099 (ssp245); 2015-2099 (ssp585) | J6: °C | K6: Daily; Monthly | L6: National | M6: 25 km (Grid) | N6: NetCDF | O6: Restricted | P6: https://clim-webbased.dcce.go.th/DataServices | Q6: - | R6: Model/Source: RegCM5 (EC-Earth3-Veg) · Variable: tasmin | S6: Website Climate Data Visualization | T6: Website | U6: Restricted
A7: DCCE_2_14 | B7: อุณหภูมิเฉลี่ย (RegCM5, EC-Earth3-Veg) | C7: Forward-looking | D7: Climate Driver | E7: CLIMATE_DRIVER | F7: Multi-hazard | G7: Cross-cutting (หลายสาขา) | H7: Historical; Projected | I7: 1960-2014 (historical); 2015-2099 (ssp245); 2015-2099 (ssp585) | J7: °C | K7: Daily; Monthly | L7: National | M7: 25 km (Grid) | N7: NetCDF | O7: Restricted | P7: https://clim-webbased.dcce.go.th/DataServices | Q7: - | R7: Model/Source: RegCM5 (EC-Earth3-Veg) · Variable: tas | S7: Website Climate Data Visualization | T7: Website | U7: Restricted
A8: DCCE_2_15 | B8: ความชื้นสัมพัทธ์ (RegCM5, EC-Earth3-Veg) | C8: Forward-looking | D8: Climate Driver | E8: CLIMATE_DRIVER | F8: ภัยแล้ง (Drought); ไฟป่า (Wildfire) | G8: Cross-cutting (หลายสาขา) | H8: Historical; Projected | I8: 1960-2014 (historical); 2015-2099 (ssp245); 2015-2099 (ssp585) | J8: % | K8: Daily; Monthly | L8: National | M8: 25 km (Grid) | N8: NetCDF | O8: Restricted | P8: https://clim-webbased.dcce.go.th/DataServices | Q8: - | R8: Model/Source: RegCM5 (EC-Earth3-Veg) · Variable: hurs | S8: Website Climate Data Visualization | T8: Website | U8: Restricted
A9: DCCE_2_16 | B9: ปริมาณน้ำฝน (Statistical Downscaling, CMIP6) | C9: Forward-looking | D9: Climate Driver | E9: CLIMATE_DRIVER | F9: น้ำท่วม (Flood); ภัยแล้ง (Drought) | G9: Cross-cutting (หลายสาขา) | H9: Historical; Projected | I9: 1981-2014 (historical); 2015-2100 (ssp245); 2015-2100 (ssp585) | J9: mm | K9: Daily; Monthly | L9: National | M9: 5 km (Grid) | N9: NetCDF | O9: Restricted | P9: https://clim-webbased.dcce.go.th/DataServices | Q9: - | R9: Model/Source: Statistical Downscalingจาก CMIP6 GCMs (ACCESS-CM2; MIROC6; MPI-ESM1-2) · Variable: pr | S9: Website Climate Data Visualization | T9: Website | U9: Restricted
A10: DCCE_2_17 | B10: อุณหภูมิสูงสุด (Statistical Downscaling, CMIP6) | C10: Forward-looking | D10: Climate Driver | E10: CLIMATE_DRIVER | F10: คลื่นความร้อน (Heat); ภัยแล้ง (Drought) | G10: Cross-cutting (หลายสาขา) | H10: Historical; Projected | I10: 1981-2014 (historical); 2015-2100 (ssp245); 2015-2100 (ssp585) | J10: °C | K10: Daily; Monthly | L10: National | M10: 5 km (Grid) | N10: NetCDF | O10: Restricted | P10: https://clim-webbased.dcce.go.th/DataServices | Q10: - | R10: Model/Source: Statistical Downscaling(ACCESS-CM2; MIROC6; MPI-ESM1-2) · Variable: tasmax | S10: Website Climate Data Visualization | T10: Website | U10: Restricted
A11: DCCE_2_18 | B11: อุณหภูมิต่ำสุด (Statistical Downscaling, CMIP6) | C11: Forward-looking | D11: Climate Driver | E11: CLIMATE_DRIVER | F11: คลื่นความเย็น (Cold spell); คลื่นความร้อน (Heat) | G11: Cross-cutting (หลายสาขา) | H11: Historical; Projected | I11: 1981-2014 (historical); 2015-2100 (ssp245); 2015-2100 (ssp585) | J11: °C | K11: Daily; Monthly | L11: National | M11: 5 km (Grid) | N11: NetCDF | O11: Restricted | P11: https://clim-webbased.dcce.go.th/DataServices | Q11: - | R11: Model/Source: Statistical Downscaling(ACCESS-CM2; MIROC6; MPI-ESM1-2) · Variable: tasmin | S11: Website Climate Data Visualization | T11: Website | U11: Restricted
A12: DCCE_2_19 | B12: อุณหภูมิเฉลี่ย (Statistical Downscaling, CMIP6) | C12: Forward-looking | D12: Climate Driver | E12: CLIMATE_DRIVER | F12: Multi-hazard | G12: Cross-cutting (หลายสาขา) | H12: Historical; Projected | I12: 1981-2014 (historical); 2015-2100 (ssp245); 2015-2100 (ssp585) | J12: °C | K12: Daily; Monthly | L12: National | M12: 5 km (Grid) | N12: NetCDF | O12: Restricted | P12: https://clim-webbased.dcce.go.th/DataServices | Q12: SD ไม่มีข้อมูล Relative Humidity (hurs) | R12: Model/Source: Statistical Downscaling(ACCESS-CM2; MIROC6; MPI-ESM1-2) · Variable: tas | S12: Website Climate Data Visualization | T12: Website | U12: Restricted
A13: DCCE_2_2 | B13: อุณหภูมิสูงสุด (GridData, historical) | C13: Forward-looking | D13: Climate Driver | E13: CLIMATE_DRIVER | F13: Drought (ภัยแล้ง) | G13: Cross-cutting (หลายสาขา) | H13: Historical | I13: 1981-2023 | J13: °C | K13: Daily; Monthly | L13: National | M13: 25 km (Grid) | N13: NetCDF | O13: Restricted | P13: https://clim-webbased.dcce.go.th/DataServices | Q13: - | R13: Model/Source: GridData · Variable: tasmax · Scenario: historical | S13: Website Climate Data Visualization | T13: Website | U13: Restricted
... A20: DCCE_2_9 | B20: อุณหภูมิเฉลี่ย (WRF-Chem) | C20: Forward-looking | D20: Climate Driver | E20: CLIMATE_DRIVER | F20: Multi-hazard | G20: Cross-cutting (หลายสาขา) | H20: Historical; Projected | I20: 1981-2014 (historical); 2015-2099 (ssp585) | J20: °C | K20: Daily; Monthly | L20: National | M20: 25 km (Grid) | N20: NetCDF | O20: Restricted | P20: https://clim-webbased.dcce.go.th/DataServices | Q20: มีเฉพาะ ssp585 | R20: Model/Source: WRF-Chem · Variable: tas | S20: Website Climate Data Visualization | T20: Website | U20: Restricted
A21: DCCE_3_1 | B21: ความเสี่ยงสาขาการเกษตรและความมั่นคงทางอาหาร | C21: Forward-looking | D21: Composite Index | E21: COMPOSITE_INDEX | F21: Cross-cutting (ทุกภัย) | G21: Agriculture (เกษตร) | H21: Historical; Projected | I21: 1960-2014; 2015-2040; 2041-2060; 2061-2080; 2081-2100 | L21: National | M21: Province | N21: CSV | O21: Open | P21: https://ccic.dcce.go.th/riskarea | Q21: มีเฉพาะ ssp585 และ ssp245 | R21: ดัชนีรวมจาก Hazard × Exposure × Vulnerability รายจังหวัด | S21: Website ฐานข้อมูลความเสี่ยงจากการเปลี่ยนแปลงสภาพภูมิอากาศ | T21: Website | U21: Open
A22: DCCE_3_2 | B22: ความเสี่ยงสาขาการจัดการน้ำ | C22: Forward-looking | D22: Composite Index | E22: COMPOSITE_INDEX | F22: Cross-cutting (ทุกภัย) | G22: Water (น้ำ) | H22: Historical; Projected | I22: 1960-2014; 2015-2040; 2041-2060; 2061-2080; 2081-2101 | L22: National | M22: Province | N22: CSV | O22: Open | P22: https://ccic.dcce.go.th/riskarea | Q22: มีเฉพาะ ssp585 และ ssp246 | R22: ดัชนีรวมจาก Hazard × Exposure × Vulnerability รายจังหวัด | S22: Website ฐานข้อมูลความเสี่ยงจากการเปลี่ยนแปลงสภาพภูมิอากาศ | T22: Website | U22: Open
A23: DCCE_3_3 | B23: ความเสี่ยงสาขาการตั้งถิ่นฐานและความมั่นคงมนุษย์ | C23: Forward-looking | D23: Composite Index | E23: COMPOSITE_INDEX | F23: Cross-cutting (ทุกภัย) | G23: Human Settlement (ตั้งถิ่นฐาน) | H23: Historical; Projected | I23: 1960-2014; 2015-2040; 2041-2060; 2061-2080; 2081-2102 | J23: Index (0-1) | K23: Annual | L23: National | M23: Province | N23: CSV | O23: Open | P23: https://ccic.dcce.go.th/riskarea | Q23: มีเฉพาะ ssp585 และ ssp247 | R23: ดัชนีรวมจาก Hazard × Exposure × Vulnerability รายจังหวัด | S23: Website ฐานข้อมูลความเสี่ยงจากการเปลี่ยนแปลงสภาพภูมิอากาศ | T23: Website | U23: Open
A24: DCCE_3_4 | B24: ความเสี่ยงสาขาการท่องเที่ยว | C24: Forward-looking | D24: Composite Index | E24: COMPOSITE_INDEX | F24: Cross-cutting (ทุกภัย) | G24: Tourism (ท่องเที่ยว) | H24: Historical; Projected | I24: 1960-2014; 2015-2040; 2041-2060; 2061-2080; 2081-2103 | J24: Index (0-1) | K24: Annual | L24: National | M24: Province | N24: CSV | O24: Open | P24: https://ccic.dcce.go.th/riskarea | Q24: มีเฉพาะ ssp585 และ ssp248 | R24: ดัชนีรวมจาก Hazard × Exposure × Vulnerability รายจังหวัด | S24: Website ฐานข้อมูลความเสี่ยงจากการเปลี่ยนแปลงสภาพภูมิอากาศ | T24: Website | U24: Open
A25: DCCE_3_5 | B25: ความเสี่ยงสาขาทรัพยากรธรรมชาติและสิ่งแวดล้อม | C25: Forward-looking | D25: Composite Index | E25: COMPOSITE_INDEX | F25: Cross-cutting (ทุกภัย) | G25: Natural Resources (ทรัพยากรธรรมชาติ) | H25: Historical; Projected | I25: 1960-2014; 2015-2040; 2041-2060; 2061-2080; 2081-2104 | J25: Index (0-1) | K25: Annual | L25: National | M25: Province | N25: CSV | O25: Open | P25: https://ccic.dcce.go.th/riskarea | Q25: มีเฉพาะ ssp585 และ ssp249 | R25: ดัชนีรวมจาก Hazard × Exposure × Vulnerability รายจังหวัด | S25: Website ฐานข้อมูลความเสี่ยงจากการเปลี่ยนแปลงสภาพภูมิอากาศ | T25: Website | U25: Open
A26: DCCE_3_6 | B26: ความเสี่ยงสาขาสาธารณสุข | C26: Forward-looking | D26: Composite Index | E26: COMPOSITE_INDEX | F26: Cross-cutting (ทุกภัย) | G26: Public Health (สาธารณสุข) | H26: Historical; Projected | I26: 1960-2014; 2015-2040; 2041-2060; 2061-2080; 2081-2105 | J26: Index (0-1) | K26: Annual | L26: National | M26: Province | N26: CSV | O26: Open | P26: https://ccic.dcce.go.th/riskarea | Q26: มีเฉพาะ ssp585 และ ssp250 | R26: ดัชนีรวมจาก Hazard × Exposure × Vulnerability รายจังหวัด | S26: Website ฐานข้อมูลความเสี่ยงจากการเปลี่ยนแปลงสภาพภูมิอากาศ | T26: Website | U26: Open
